Workbook

Sheet Stock & Approvisionnement
A1: Stock & Approvisionnement - Stations Cable Management
A4: Équipement | B4: Type | C4: Stock initial disponible | D4: Besoin théorique max | E4: Consommé à date | F4: HS | G4: Stock restant | H4: Seuil d'alerte | I4: À commander ? | J4: Quantité commandée | K4: Reçu ?
A5: EXEMPLE - TC 630/640 → 655 | B5: Équipement principal | C5: 20 | D5: 150 | E5: 5 | F5: 5 | G5: =C5-E5-F5 -> 10 | H5: 15 | I5: =IF(H5="","À définir",IF(G5<H5,"Oui","Non")) -> Oui | J5: 30 | K5: Non
A6: TC 630/640 → 655 | B6: Équipement principal | C6: 52 | D6: 40 | E6: 6 | F6: 0 | G6: =C6-E6-F6 -> 46 | H6: 30 | I6: =IF(H6="","À définir",IF(G6<H6,"Oui","Non")) -> Non
A7: Imprimante ZT 411/410 | B7: Équipement principal | C7: 13 | D7: 7 | E7: 0 | F7: 12 | G7: =C7-E7-F7 -> 1 | H7: 5 | I7: =IF(H7="","À définir",IF(G7<H7,"Oui","Non")) -> Oui
A8: Imprimante ZD 621 T | B8: Équipement principal | C8: 7 | D8: 5 | E8: 0 | F8: 7 | G8: =C8-E8-F8 -> 0 | H8: 5 | I8: =IF(H8="","À définir",IF(G8<H8,"Oui","Non")) -> Oui
A9: Imprimante ZD 621 | B9: Équipement principal | C9: 3 | D9: 12 | E9: 0 | F9: 0 | G9: =C9-E9-F9 -> 3 | H9: 5 | I9: =IF(H9="","À définir",IF(G9<H9,"Oui","Non")) -> Oui
A10: Genovation | B10: Équipement principal | C10: 5 | D10: n/a | E10: 0 | F10: 0 | G10: =C10-E10-F10 -> 5 | H10: 3 | I10: =IF(H10="","À définir",IF(G10<H10,"Oui","Non")) -> Non
A11: Clavier | B11: Équipement principal | C11: 52 | D11: n/a | E11: 0 | F11: 0 | G11: =C11-E11-F11 -> 52 | H11: 25 | I11: =IF(H11="","À définir",IF(G11<H11,"Oui","Non")) -> Non
A12: NFC Connect | B12: Équipement principal | C12: 17 | D12: n/a | E12: 0 | F12: 0 | G12: =C12-E12-F12 -> 17 | H12: 15 | I12: =IF(H12="","À définir",IF(G12<H12,"Oui","Non")) -> Non
A13: Support 2D | B13: Consommable | C13: 180 | D13: n/a | E13: 0 | F13: 0 | G13: =C13-E13-F13 -> 180 | H13: 70 | I13: =IF(H13="","À définir",IF(G13<H13,"Oui","Non")) -> Non
A14: Rondelle plate | B14: Consommable | C14: 0 | D14: n/a | E14: 0 | F14: 0 | G14: =C14-E14-F14 -> 0 | I14: =IF(H14="","À définir",IF(G14<H14,"Oui","Non")) -> À définir
A15: Autocollant | B15: Consommable | C15: 0 | D15: n/a | E15: 0 | F15: 0 | G15: =C15-E15-F15 -> 0 | I15: =IF(H15="","À définir",IF(G15<H15,"Oui","Non")) -> À définir
A16: Protection scanner central | B16: Consommable | C16: 0 | D16: n/a | E16: 0 | F16: 0 | G16: =C16-E16-F16 -> 0 | I16: =IF(H16="","À définir",IF(G16<H16,"Oui","Non")) -> À définir
A17: Secure IT | B17: Consommable | C17: 120 | D17: n/a | E17: 0 | F17: 0 | G17: =C17-E17-F17 -> 120 | H17: 70 | I17: =IF(H17="","À définir",IF(G17<H17,"Oui","Non")) -> Non
A18: Câbles | B18: Consommable | C18: 0 | D18: n/a | E18: 0 | F18: 0 | G18: =C18-E18-F18 -> 0 | I18: =IF(H18="","À définir",IF(G18<H18,"Oui","Non")) -> À définir
A19: Rallonges | B19: Consommable | C19: 0 | D19: n/a | E19: 0 | F19: 0 | G19: =C19-E19-F19 -> 0 | I19: =IF(H19="","À définir",IF(G19<H19,"Oui","Non")) -> À définir
A20: Extension rallonge | B20: Consommable | C20: 0 | D20: n/a | E20: 0 | F20: 0 | G20: =C20-E20-F20 -> 0 | I20: =IF(H20="","À définir",IF(G20<H20,"Oui","Non")) -> À définir
A21: Colson | B21: Consommable | C21: 0 | D21: n/a | E21: 0 | F21: 0 | G21: =C21-E21-F21 -> 0 | I21: =IF(H21="","À définir",IF(G21<H21,"Oui","Non")) -> À définir
A22: Serre-câbles réutilisables | B22: Consommable | C22: 0 | D22: n/a | E22: 0 | F22: 0 | G22: =C22-E22-F22 -> 0 | I22: =IF(H22="","À définir",IF(G22<H22,"Oui","Non")) -> À définir
A23: Clips câbles autocollants | B23: Consommable | C23: 0 | D23: n/a | E23: 0 | F23: 0 | G23: =C23-E23-F23 -> 0 | I23: =IF(H23="","À définir",IF(G23<H23,"Oui","Non")) -> À définir
A25: Note : ZD 620 (3), GX 420d (8) et GX 430t (1) sont des modeles distincts, fonctionnels, presents en petite quantite sur quelques process (Pack single, PCNS, P2R, Problem Solve) -- ils ne sont pas suivis ici car aucun remplacement n'est prevu (remplacement uniquement si usure.
A26: Note : les plafonds "Besoin theorique max" (TC655 139 / ZT 16 / ZD621 167) sont saisis a la main, car ils dependent de quel equipement chaque process/sous-type utilise reellement (audit terrain §1b/§2c), une donnee plus fine que le simple total de stations. Si la liste des process change (onglet Planning), revalider ces 3 plafonds a la main par rapport a l'audit avant de commander.
A29: Répartition équipement principal par process (audit terrain) — référence, ne se met pas à jour automatiquement
A30: Process | B30: TC | C30: ZT (411/410) | D30: ZD / GX
A31: Single 1, Single 2 | B31: TC630 (19) + TC655 (33) | C31: — | D31: ZD621 (46) + GX420d (6)
A32: PCNS 1, PCNS 2 | B32: TC630 (4) + TC640 (1) + TC655 (11) | C32: corrigé : ZT utilisée (détail par poste à saisir) | D32: ZD621 (13) + ZD620 (2) + GX420d (1)
A33: KO | B33: TC640 (1) + TC655 (3) | C33: ZT411 (3) + ZT410 (1) | D33: —
A34: P2R | B34: TC655 (60) | C34: — | D34: ZD621 (58) + GX420d (1) + ZD620 (1)
A36: Note : le tableau ci-dessus provient de l'audit terrain d'origine. Correction actée pour PCNS : contrairement à la mention « — » sur ZT, PCNS utilise bien 2 types d'imprimante (ZD et ZT) — cf. onglet PCNS, colonne «Imprimante ZT».

Sheet Planning - Calendrier
A1: Planning - Calendrier - Stations Cable Management
A4: Date de démarrage : | B4: 46265 | C4: Modifiable
A5: Shutdown (Journée entière) : | B5: 46267 | C5: 46274 | G5: Ajout possible
A6: Cadence retenue (décision) : | B6: 2 stations/jour | C6: Modifiable
A8: Tableau de référence — process (ordre de traitement retenu, de haut en bas)
A9: Process | B9: Nb stations | C9: Temps/station (min) | D9: Cumul fin (aide) | E9: Rang (aide)
A10: Single 1 | B10: 26 | C10: 180 | D10: =SUM($B$10:B10) -> 26 | E10: =IF(A10="","",SUMPRODUCT(($A$10:A10<>"")*1)) -> 1
A11: Single 2 | B11: 26 | C11: 180 | D11: =SUM($B$10:B11) -> 52 | E11: =IF(A11="","",SUMPRODUCT(($A$10:A11<>"")*1)) -> 2
A12: PCNS 1 | B12: 9 | C12: 150 | D12: =SUM($B$10:B12) -> 61 | E12: =IF(A12="","",SUMPRODUCT(($A$10:A12<>"")*1)) -> 3
A13: PCNS 2 | B13: 7 | C13: 150 | D13: =SUM($B$10:B13) -> 68 | E13: =IF(A13="","",SUMPRODUCT(($A$10:A13<>"")*1)) -> 4
A14: KO | B14: 4 | C14: 180 | D14: =SUM($B$10:B14) -> 72 | E14: =IF(A14="","",SUMPRODUCT(($A$10:A14<>"")*1)) -> 5
A15: P2R | B15: 60 | C15: 90 | D15: =SUM($B$10:B15) -> 132 | E15: =IF(A15="","",SUMPRODUCT(($A$10:A15<>"")*1)) -> 6
A16: Jackpot | B16: 2 | C16: 180 | D16: =SUM($B$10:B16) -> 134 | E16: =IF(A16="","",SUMPRODUCT(($A$10:A16<>"")*1)) -> 7
A17: VRET | B17: 4 | C17: 150 | D17: =SUM($B$10:B17) -> 138 | E17: =IF(A17="","",SUMPRODUCT(($A$10:A17<>"")*1)) -> 8
A18: GiftWrap | B18: 6 | C18: 150 | D18: =SUM($B$10:B18) -> 144 | E18: =IF(A18="","",SUMPRODUCT(($A$10:A18<>"")*1)) -> 9
A19: Problem Solve | B19: 4 | C19: 150 | D19: =SUM($B$10:B19) -> 148 | E19: =IF(A19="","",SUMPRODUCT(($A$10:A19<>"")*1)) -> 10
A20: Shipping | B20: 11 | C20: 30 | D20: =SUM($B$10:B20) -> 159 | E20: =IF(A20="","",SUMPRODUCT(($A$10:A20<>"")*1)) -> 11
A21: XLI4 Receive 3 | B21: 16 | C21: 30 | D21: =SUM($B$10:B21) -> 175 | E21: =IF(A21="","",SUMPRODUCT(($A$10:A21<>"")*1)) -> 12
... A25: XLI4 Sort 2 | B25: 6 | C25: 30 | D25: =SUM($B$10:B25) -> 199 | E25: =IF(A25="","",SUMPRODUCT(($A$10:A25<>"")*1)) -> 16
A27: Total stations (calcul automatique) : | B27: =SUM($B$10:$B$25) -> 199
A28: Ordre retenu : Single 1 → Single 2 → PCNS 1 → PCNS 2 → KO → P2R → Jackpot → VRET → GiftWrap → Problem Solve → Shipping → XLI4 Receive 3 → XLI4 Receive 1 → XLI4 Receive 2 → XLI4 Sort 1 → XLI4 Sort 2 (ordre du tableau ci-dessus, de haut en bas).
A29: Ajout d'un process : remplissez la prochaine ligne vide du tableau ci-dessus (Process / Nb stations / Temps par station). Retrait d'un process : videz ces 3 cellules sur sa ligne, même au milieu de la liste (la colonne "Rang" gère les trous). Dans les deux cas, le "Total stations", les 3 tableaux ci-dessous (comparatif, détail par process, résumé) et le moteur journalier caché se recalculent automatiquement, sans toucher à aucune formule.
A31: Tableau 1 - Comparatif des 3 cadences (calcul automatique)
A32: Cadence | B32: Rythme | C32: Durée totale (jours ouvrés) | D32: Durée totale (≈ mois) | E32: Projet fini le
A33: 1 station/jour | B33: 1/jour (normal) | C33: =SUMPRODUCT(($C$66:$C$365<TotalStations)*1) -> 197 | D33: =IFERROR(ROUND((E33-$B$4)/30,1),"") -> 9.1 | E33: =IFERROR(INDEX($A$66:$A$365,SUMPRODUCT(($C$66:$C$365<TotalStations)*1)),"Hors plage (étendre le calendrier)") -> 46539
A34: 2 stations/jour | B34: 2/jour (normal) | C34: =SUMPRODUCT(($H$66:$H$365<TotalStations)*1) -> 100 | D34: =IFERROR(ROUND((E34-$B$4)/30,1),"") -> 4.6 | E34: =IFERROR(INDEX($A$66:$A$365,SUMPRODUCT(($H$66:$H$365<TotalStations)*1)),"Hors plage (étendre le calendrier)") -> 46402
A35: Plein temps (7h/jour dédiées) | B35: Variable (⌊420÷t⌋) | C35: =SUMPRODUCT(($M$66:$M$365<TotalStations)*1) -> 63 | D35: =IFERROR(ROUND((E35-$B$4)/30,1),"") -> 2.9 | E35: =IFERROR(INDEX($A$66:$A$365,SUMPRODUCT(($M$66:$M$365<TotalStations)*1)),"Hors plage (étendre le calendrier)") -> 46351
A37: Tableau 2 - Détail par process - dates par cadence
A38: Process | B38: Nb stations | C38: Temps/station (min) | D38: Terminé le (1 station/jour) | E38: Terminé le (2 stations/jour) | F38: Terminé le (Plein temps 7h/jour)
A39: =IF(A10="","",A10) -> Single 1 | B39: =IF(A10="","",B10) -> 26 | C39: =IF(A10="","",C10) -> 180 | D39: =IF(A39="","",IFERROR(INDEX($A$66:$A$365,SUMPRODUCT(($C$66:$C$365<D10)*1)),"Hors plage")) -> 46296 | E39: =IF(A39="","",IFERROR(INDEX($A$66:$A$365,SUMPRODUCT(($H$66:$H$365<D10)*1)),"Hors plage")) -> 46281 | F39: =IF(A39="","",IFERROR(INDEX($A$66:$A$365,SUMPRODUCT(($M$66:$M$365<D10)*1)),"Hors plage")) -> 46281
A40: =IF(A11="","",A11) -> Single 2 | B40: =IF(A11="","",B11) -> 26 | C40: =IF(A11="","",C11) -> 180 | D40: =IF(A40="","",IFERROR(INDEX($A$66:$A$365,SUMPRODUCT(($C$66:$C$365<D11)*1)),"Hors plage")) -> 46332 | E40: =IF(A40="","",IFERROR(INDEX($A$66:$A$365,SUMPRODUCT(($H$66:$H$365<D11)*1)),"Hors plage")) -> 46300 | F40: =IF(A40="","",IFERROR(INDEX($A$66:$A$365,SUMPRODUCT(($M$66:$M$365<D11)*1)),"Hors plage")) -> 46300
A41: =IF(A12="","",A12) -> PCNS 1 | B41: =IF(A12="","",B12) -> 9 | C41: =IF(A12="","",C12) -> 150 | D41: =IF(A41="","",IFERROR(INDEX($A$66:$A$365,SUMPRODUCT(($C$66:$C$365<D12)*1)),"Hors plage")) -> 46345 | E41: =IF(A41="","",IFERROR(INDEX($A$66:$A$365,SUMPRODUCT(($H$66:$H$365<D12)*1)),"Hors plage")) -> 46307 | F41: =IF(A41="","",IFERROR(INDEX($A$66:$A$365,SUMPRODUCT(($M$66:$M$365<D12)*1)),"Hors plage")) -> 46307
A42: =IF(A13="","",A13) -> PCNS 2 | B42: =IF(A13="","",B13) -> 7 | C42: =IF(A13="","",C13) -> 150 | D42: =IF(A42="","",IFERROR(INDEX($A$66:$A$365,SUMPRODUCT(($C$66:$C$365<D13)*1)),"Hors plage")) -> 46356 | E42: {=IF(A42="","",IFERROR(_xlfn.single(INDEX($A$66:$A$365,SUMPRODUCT(($H$66:$H$365<D13)*1))),"Hors plage"))} -> Hors plage | F42: =IF(A42="","",IFERROR(INDEX($A$66:$A$365,SUMPRODUCT(($M$66:$M$365<D13)*1)),"Hors plage")) -> 46310
A43: =IF(A14="","",A14) -> KO | B43: =IF(A14="","",B14) -> 4 | C43: =IF(A14="","",C14) -> 180 | D43: =IF(A43="","",IFERROR(INDEX($A$66:$A$365,SUMPRODUCT(($C$66:$C$365<D14)*1)),"Hors plage")) -> 46360 | E43: =IF(A43="","",IFERROR(INDEX($A$66:$A$365,SUMPRODUCT(($H$66:$H$365<D14)*1)),"Hors plage")) -> 46314 | F43: =IF(A43="","",IFERROR(INDEX($A$66:$A$365,SUMPRODUCT(($M$66:$M$365<D14)*1)),"Hors plage")) -> 46314
A44: =IF(A15="","",A15) -> P2R | B44: =IF(A15="","",B15) -> 60 | C44: =IF(A15="","",C15) -> 90 | D44: =IF(A44="","",IFERROR(INDEX($A$66:$A$365,SUMPRODUCT(($C$66:$C$365<D15)*1)),"Hors plage")) -> 46444 | E44: =IF(A44="","",IFERROR(INDEX($A$66:$A$365,SUMPRODUCT(($H$66:$H$365<D15)*1)),"Hors plage")) -> 46356 | F44: =IF(A44="","",IFERROR(INDEX($A$66:$A$365,SUMPRODUCT(($M$66:$M$365<D15)*1)),"Hors plage")) -> 46335
A45: =IF(A16="","",A16) -> Jackpot | B45: =IF(A16="","",B16) -> 2 | C45: =IF(A16="","",C16) -> 180 | D45: =IF(A45="","",IFERROR(INDEX($A$66:$A$365,SUMPRODUCT(($C$66:$C$365<D16)*1)),"Hors plage")) -> 46448 | E45: =IF(A45="","",IFERROR(INDEX($A$66:$A$365,SUMPRODUCT(($H$66:$H$365<D16)*1)),"Hors plage")) -> 46357 | F45: =IF(A45="","",IFERROR(INDEX($A$66:$A$365,SUMPRODUCT(($M$66:$M$365<D16)*1)),"Hors plage")) -> 46336
A46: =IF(A17="","",A17) -> VRET | B46: =IF(A17="","",B17) -> 4 | C46: =IF(A17="","",C17) -> 150 | D46: =IF(A46="","",IFERROR(INDEX($A$66:$A$365,SUMPRODUCT(($C$66:$C$365<D17)*1)),"Hors plage")) -> 46454 | E46: =IF(A46="","",IFERROR(INDEX($A$66:$A$365,SUMPRODUCT(($H$66:$H$365<D17)*1)),"Hors plage")) -> 46359 | F46: =IF(A46="","",IFERROR(INDEX($A$66:$A$365,SUMPRODUCT(($M$66:$M$365<D17)*1)),"Hors plage")) -> 46338
A47: =IF(A18="","",A18) -> GiftWrap | B47: =IF(A18="","",B18) -> 6 | C47: =IF(A18="","",C18) -> 150 | D47: =IF(A47="","",IFERROR(INDEX($A$66:$A$365,SUMPRODUCT(($C$66:$C$365<D18)*1)),"Hors plage")) -> 46462 | E47: =IF(A47="","",IFERROR(INDEX($A$66:$A$365,SUMPRODUCT(($H$66:$H$365<D18)*1)),"Hors plage")) -> 46364 | F47: =IF(A47="","",IFERROR(INDEX($A$66:$A$365,SUMPRODUCT(($M$66:$M$365<D18)*1)),"Hors plage")) -> 46343
A48: =IF(A19="","",A19) -> Problem Solve | B48: =IF(A19="","",B19) -> 4 | C48: =IF(A19="","",C19) -> 150 | D48: =IF(A48="","",IFERROR(INDEX($A$66:$A$365,SUMPRODUCT(($C$66:$C$365<D19)*1)),"Hors plage")) -> 46468 | E48: =IF(A48="","",IFERROR(INDEX($A$66:$A$365,SUMPRODUCT(($H$66:$H$365<D19)*1)),"Hors plage")) -> 46366 | F48: =IF(A48="","",IFERROR(INDEX($A$66:$A$365,SUMPRODUCT(($M$66:$M$365<D19)*1)),"Hors plage")) -> 46345
A49: =IF(A20="","",A20) -> Shipping | B49: =IF(A20="","",B20) -> 11 | C49: =IF(A20="","",C20) -> 30 | D49: =IF(A49="","",IFERROR(INDEX($A$66:$A$365,SUMPRODUCT(($C$66:$C$365<D20)*1)),"Hors plage")) -> 46483 | E49: =IF(A49="","",IFERROR(INDEX($A$66:$A$365,SUMPRODUCT(($H$66:$H$365<D20)*1)),"Hors plage")) -> 46374 | F49: =IF(A49="","",IFERROR(INDEX($A$66:$A$365,SUMPRODUCT(($M$66:$M$365<D20)*1)),"Hors plage")) -> 46346
...

Sheet Dashboard
B2: TABLEAU DE BORD — SUIVI DES STATIONS
B3: Périmètre suivi en détail : Single 1, Single 2, PCNS 1, PCNS 2, KO, P2R — 132 stations sur 199 au total (voir onglet "Planning - Calendrier" pour le reste du projet).
B5: 1. VUE D'ENSEMBLE — TOUS PROCESS SUIVIS CONFONDUS
B6: Total stations | C6: Fait | D6: En cours | E6: À faire | F6: % avancement | G6: Temps restant (h)
B7: 132 | C7: =COUNTIF('Single 1'!L3:L16,"Fait")+COUNTIF('Single 1'!L18:L29,"Fait")+COUNTIF('Single 2'!L3:L16,"Fait")+COUNTIF('Single 2'!L18:L29,"Fait")+COUNTIF(PCNS!L3:L11,"Fait")+COUNTIF(PCNS!L13:L19,"Fait")+COUNTIF(KO!L2:L5,"Fait")+COUNTIF(P2R!L2:L61,"Fait") -> 10 | D7: =COUNTIF('Single 1'!L3:L16,"En cours")+COUNTIF('Single 1'!L18:L29,"En cours")+COUNTIF('Single 2'!L3:L16,"En cours")+COUNTIF('Single 2'!L18:L29,"En cours")+COUNTIF(PCNS!L3:L11,"En cours")+COUNTIF(PCNS!L13:L19,"En cours")+COUNTIF(KO!L2:L5,"En cours")+COUNTIF(P2R!L2:L61,"En cours") -> 1 | E7: =COUNTIF('Single 1'!L3:L16,"A faire")+COUNTIF('Single 1'!L18:L29,"A faire")+COUNTIF('Single 2'!L3:L16,"A faire")+COUNTIF('Single 2'!L18:L29,"A faire")+COUNTIF(PCNS!L3:L11,"A faire")+COUNTIF(PCNS!L13:L19,"A faire")+COUNTIF(KO!L2:L5,"A faire")+COUNTIF(P2R!L2:L61,"A faire") -> 121 | F7: =C7/B7 -> 0.075757576 | G7: =SUM('Single 1'!O3:O16,'Single 1'!O18:O29,'Single 2'!O3:O16,'Single 2'!O18:O29,PCNS!O3:O11,PCNS!O13:O19,KO!O2:O5,P2R!O2:O61)/60 -> 248.91667
B9: 2. AVANCEMENT PAR PROCESS
B10: Process | C10: Total | D10: Fait | E10: En cours | F10: À faire | G10: % avancement | H10: Temps restant (min)
B11: Single 1 | C11: 26 | D11: =COUNTIF('Single 1'!L3:L16,"Fait")+COUNTIF('Single 1'!L18:L29,"Fait") -> 4 | E11: =COUNTIF('Single 1'!L3:L16,"En cours")+COUNTIF('Single 1'!L18:L29,"En cours") -> 1 | F11: =COUNTIF('Single 1'!L3:L16,"A faire")+COUNTIF('Single 1'!L18:L29,"A faire") -> 21 | G11: =D11/C11 -> 0.15384615 | H11: =SUM('Single 1'!O3:O16,'Single 1'!O18:O29) -> 3310
B12: Single 2 | C12: 26 | D12: =COUNTIF('Single 2'!L3:L16,"Fait")+COUNTIF('Single 2'!L18:L29,"Fait") -> 6 | E12: =COUNTIF('Single 2'!L3:L16,"En cours")+COUNTIF('Single 2'!L18:L29,"En cours") -> 0 | F12: =COUNTIF('Single 2'!L3:L16,"A faire")+COUNTIF('Single 2'!L18:L29,"A faire") -> 20 | G12: =D12/C12 -> 0.23076923 | H12: =SUM('Single 2'!O3:O16,'Single 2'!O18:O29) -> 3105
B13: PCNS 1 | C13: 9 | D13: =COUNTIF(PCNS!L3:L11,"Fait") -> 0 | E13: =COUNTIF(PCNS!L3:L11,"En cours") -> 0 | F13: =COUNTIF(PCNS!L3:L11,"A faire") -> 9 | G13: =D13/C13 -> 0 | H13: =SUM(PCNS!O3:O11) -> 1350
B14: PCNS 2 | C14: 7 | D14: =COUNTIF(PCNS!L13:L19,"Fait") -> 0 | E14: =COUNTIF(PCNS!L13:L19,"En cours") -> 0 | F14: =COUNTIF(PCNS!L13:L19,"A faire") -> 7 | G14: =D14/C14 -> 0 | H14: =SUM(PCNS!O13:O19) -> 1050
B15: KO | C15: 4 | D15: =COUNTIF(KO!L2:L5,"Fait") -> 0 | E15: =COUNTIF(KO!L2:L5,"En cours") -> 0 | F15: =COUNTIF(KO!L2:L5,"A faire") -> 4 | G15: =D15/C15 -> 0 | H15: =SUM(KO!O2:O5) -> 720
B16: P2R | C16: 60 | D16: =COUNTIF(P2R!L2:L61,"Fait") -> 0 | E16: =COUNTIF(P2R!L2:L61,"En cours") -> 0 | F16: =COUNTIF(P2R!L2:L61,"A faire") -> 60 | G16: =D16/C16 -> 0 | H16: =SUM(P2R!O2:O61) -> 5400
B17: TOTAL | C17: =SUM(C11:C16) -> 132 | D17: =SUM(D11:D16) -> 10 | E17: =SUM(E11:E16) -> 1 | F17: =SUM(F11:F16) -> 121 | G17: =D17/C17 -> 0.075757576 | H17: =SUM(H11:H16) -> 14935
B19: 3. REMPLACEMENT TC — OBJECTIF T655
B20: Statut | C20: Compte | D20: % du total suivi
B21: T655 (fait) | C21: =COUNTIF('Single 1'!B3:B16,"T655")+COUNTIF('Single 1'!B18:B29,"T655")+COUNTIF('Single 2'!B3:B16,"T655")+COUNTIF('Single 2'!B18:B29,"T655")+COUNTIF(PCNS!B3:B11,"T655")+COUNTIF(PCNS!B13:B19,"T655")+COUNTIF(KO!B2:B5,"T655")+COUNTIF(P2R!B2:B61,"T655") -> 93 | D21: =C21/$B$7 -> 0.70454545
B22: T630 (à remplacer) | C22: =COUNTIF('Single 1'!B3:B16,"T630")+COUNTIF('Single 1'!B18:B29,"T630")+COUNTIF('Single 2'!B3:B16,"T630")+COUNTIF('Single 2'!B18:B29,"T630")+COUNTIF(PCNS!B3:B11,"T630")+COUNTIF(PCNS!B13:B19,"T630")+COUNTIF(KO!B2:B5,"T630")+COUNTIF(P2R!B2:B61,"T630") -> 19 | D22: =C22/$B$7 -> 0.14393939
B23: T640 (à remplacer) | C23: =COUNTIF('Single 1'!B3:B16,"T640")+COUNTIF('Single 1'!B18:B29,"T640")+COUNTIF('Single 2'!B3:B16,"T640")+COUNTIF('Single 2'!B18:B29,"T640")+COUNTIF(PCNS!B3:B11,"T640")+COUNTIF(PCNS!B13:B19,"T640")+COUNTIF(KO!B2:B5,"T640")+COUNTIF(P2R!B2:B61,"T640") -> 0 | D23: =C23/$B$7 -> 0
B24: Non renseigné / à saisir | C24: =$B$7-C21-C22-C23 -> 20 | D24: =C24/$B$7 -> 0.15151515
B26: 4. VALIDATIONS QUALITÉ (checklist par poste, tous process suivis)
B27: Vérification | C27: OK | D27: Pas OK | E27: Total saisi | F27: % OK
B28: Genovation déplacé | C28: =COUNTIF('Single 1'!E3:E16,"OK")+COUNTIF('Single 1'!E18:E29,"OK")+COUNTIF('Single 2'!E3:E16,"OK")+COUNTIF('Single 2'!E18:E29,"OK")+COUNTIF(PCNS!E3:E11,"OK")+COUNTIF(PCNS!E13:E19,"OK")+COUNTIF(KO!E2:E5,"OK")+COUNTIF(P2R!E2:E61,"OK") -> 52 | D28: =COUNTIF('Single 1'!E3:E16,"Pas OK")+COUNTIF('Single 1'!E18:E29,"Pas OK")+COUNTIF('Single 2'!E3:E16,"Pas OK")+COUNTIF('Single 2'!E18:E29,"Pas OK")+COUNTIF(PCNS!E3:E11,"Pas OK")+COUNTIF(PCNS!E13:E19,"Pas OK")+COUNTIF(KO!E2:E5,"Pas OK")+COUNTIF(P2R!E2:E61,"Pas OK") -> 0 | E28: =C28+D28 -> 52 | F28: =IF(E28>0,C28/E28,0) -> 1
B29: Scanner remplacé | C29: =COUNTIF('Single 1'!F3:F16,"OK")+COUNTIF('Single 1'!F18:F29,"OK")+COUNTIF('Single 2'!F3:F16,"OK")+COUNTIF('Single 2'!F18:F29,"OK")+COUNTIF(PCNS!F3:F11,"OK")+COUNTIF(PCNS!F13:F19,"OK")+COUNTIF(KO!F2:F5,"OK")+COUNTIF(P2R!F2:F61,"OK") -> 52 | D29: =COUNTIF('Single 1'!F3:F16,"Pas OK")+COUNTIF('Single 1'!F18:F29,"Pas OK")+COUNTIF('Single 2'!F3:F16,"Pas OK")+COUNTIF('Single 2'!F18:F29,"Pas OK")+COUNTIF(PCNS!F3:F11,"Pas OK")+COUNTIF(PCNS!F13:F19,"Pas OK")+COUNTIF(KO!F2:F5,"Pas OK")+COUNTIF(P2R!F2:F61,"Pas OK") -> 0 | E29: =C29+D29 -> 52 | F29: =IF(E29>0,C29/E29,0) -> 1
B30: Système Mask en place | C30: =COUNTIF('Single 1'!G3:G16,"OK")+COUNTIF('Single 1'!G18:G29,"OK")+COUNTIF('Single 2'!G3:G16,"OK")+COUNTIF('Single 2'!G18:G29,"OK")+COUNTIF(PCNS!G3:G11,"OK")+COUNTIF(PCNS!G13:G19,"OK")+COUNTIF(KO!G2:G5,"OK")+COUNTIF(P2R!G2:G61,"OK") -> 52 | D30: =COUNTIF('Single 1'!G3:G16,"Pas OK")+COUNTIF('Single 1'!G18:G29,"Pas OK")+COUNTIF('Single 2'!G3:G16,"Pas OK")+COUNTIF('Single 2'!G18:G29,"Pas OK")+COUNTIF(PCNS!G3:G11,"Pas OK")+COUNTIF(PCNS!G13:G19,"Pas OK")+COUNTIF(KO!G2:G5,"Pas OK")+COUNTIF(P2R!G2:G61,"Pas OK") -> 0 | E30: =C30+D30 -> 52 | F30: =IF(E30>0,C30/E30,0) -> 1
B31: Secure IT - Plaque | C31: =COUNTIF('Single 1'!H3:H16,"OK")+COUNTIF('Single 1'!H18:H29,"OK")+COUNTIF('Single 2'!H3:H16,"OK")+COUNTIF('Single 2'!H18:H29,"OK")+COUNTIF(PCNS!H3:H11,"OK")+COUNTIF(PCNS!H13:H19,"OK")+COUNTIF(KO!H2:H5,"OK")+COUNTIF(P2R!H2:H61,"OK") -> 52 | D31: =COUNTIF('Single 1'!H3:H16,"Pas OK")+COUNTIF('Single 1'!H18:H29,"Pas OK")+COUNTIF('Single 2'!H3:H16,"Pas OK")+COUNTIF('Single 2'!H18:H29,"Pas OK")+COUNTIF(PCNS!H3:H11,"Pas OK")+COUNTIF(PCNS!H13:H19,"Pas OK")+COUNTIF(KO!H2:H5,"Pas OK")+COUNTIF(P2R!H2:H61,"Pas OK") -> 0 | E31: =C31+D31 -> 52 | F31: =IF(E31>0,C31/E31,0) -> 1
B32: Secure IT - Câble | C32: =COUNTIF('Single 1'!I3:I16,"OK")+COUNTIF('Single 1'!I18:I29,"OK")+COUNTIF('Single 2'!I3:I16,"OK")+COUNTIF('Single 2'!I18:I29,"OK")+COUNTIF(PCNS!I3:I11,"OK")+COUNTIF(PCNS!I13:I19,"OK")+COUNTIF(KO!I2:I5,"OK")+COUNTIF(P2R!I2:I61,"OK") -> 10 | D32: =COUNTIF('Single 1'!I3:I16,"Pas OK")+COUNTIF('Single 1'!I18:I29,"Pas OK")+COUNTIF('Single 2'!I3:I16,"Pas OK")+COUNTIF('Single 2'!I18:I29,"Pas OK")+COUNTIF(PCNS!I3:I11,"Pas OK")+COUNTIF(PCNS!I13:I19,"Pas OK")+COUNTIF(KO!I2:I5,"Pas OK")+COUNTIF(P2R!I2:I61,"Pas OK") -> 42 | E32: =C32+D32 -> 52 | F32: =IF(E32>0,C32/E32,0) -> 0.19230769
B33: Support 3D pad | C33: =COUNTIF('Single 1'!J3:J16,"OK")+COUNTIF('Single 1'!J18:J29,"OK")+COUNTIF('Single 2'!J3:J16,"OK")+COUNTIF('Single 2'!J18:J29,"OK")+COUNTIF(PCNS!J3:J11,"OK")+COUNTIF(PCNS!J13:J19,"OK")+COUNTIF(KO!J2:J5,"OK")+COUNTIF(P2R!J2:J61,"OK") -> 10 | D33: =COUNTIF('Single 1'!J3:J16,"Pas OK")+COUNTIF('Single 1'!J18:J29,"Pas OK")+COUNTIF('Single 2'!J3:J16,"Pas OK")+COUNTIF('Single 2'!J18:J29,"Pas OK")+COUNTIF(PCNS!J3:J11,"Pas OK")+COUNTIF(PCNS!J13:J19,"Pas OK")+COUNTIF(KO!J2:J5,"Pas OK")+COUNTIF(P2R!J2:J61,"Pas OK") -> 42 | E33: =C33+D33 -> 52 | F33: =IF(E33>0,C33/E33,0) -> 0.19230769
B34: Étiquetage | C34: =COUNTIF('Single 1'!K3:K16,"OK")+COUNTIF('Single 1'!K18:K29,"OK")+COUNTIF('Single 2'!K3:K16,"OK")+COUNTIF('Single 2'!K18:K29,"OK")+COUNTIF(PCNS!K3:K11,"OK")+COUNTIF(PCNS!K13:K19,"OK")+COUNTIF(KO!K2:K5,"OK")+COUNTIF(P2R!K2:K61,"OK") -> 0 | D34: =COUNTIF('Single 1'!K3:K16,"Pas OK")+COUNTIF('Single 1'!K18:K29,"Pas OK")+COUNTIF('Single 2'!K3:K16,"Pas OK")+COUNTIF('Single 2'!K18:K29,"Pas OK")+COUNTIF(PCNS!K3:K11,"Pas OK")+COUNTIF(PCNS!K13:K19,"Pas OK")+COUNTIF(KO!K2:K5,"Pas OK")+COUNTIF(P2R!K2:K61,"Pas OK") -> 52 | E34: =C34+D34+COUNTIF('Single 1'!K3:K16,"Partiel")+COUNTIF('Single 1'!K18:K29,"Partiel")+COUNTIF('Single 2'!K3:K16,"Partiel")+COUNTIF('Single 2'!K18:K29,"Partiel")+COUNTIF(PCNS!K3:K11,"Partiel")+COUNTIF(PCNS!K13:K19,"Partiel")+COUNTIF(KO!K2:K5,"Partiel")+COUNTIF(P2R!K2:K61,"Partiel") -> 52 | F34: =IF(E34>0,C34/E34,0) -> 0
B35: TOTAL | C35: =SUM(C28:C34) -> 228 | D35: =SUM(D28:D34) -> 136 | E35: =SUM(E28:E34) -> 364 | F35: =IF(E35>0,C35/E35,0) -> 0.62637363
B37: 5. IMPRIMANTES — COUVERTURE ZD / ZT
B38: Type | C38: Renseigné | D38: N/A (non utilisé) | E38: À saisir | F38: Total stations
B39: Imprimante ZD | C39: =$B$7-D39-E39 -> 0 | D39: =COUNTIF('Single 1'!C3:C16,"N/A")+COUNTIF('Single 1'!C18:C29,"N/A")+COUNTIF('Single 2'!C3:C16,"N/A")+COUNTIF('Single 2'!C18:C29,"N/A")+COUNTIF(PCNS!C3:C11,"N/A")+COUNTIF(PCNS!C13:C19,"N/A")+COUNTIF(KO!C2:C5,"N/A")+COUNTIF(P2R!C2:C61,"N/A") -> 4 | E39: =COUNTBLANK('Single 1'!C3:C16)+COUNTBLANK('Single 1'!C18:C29)+COUNTBLANK('Single 2'!C3:C16)+COUNTBLANK('Single 2'!C18:C29)+COUNTBLANK(PCNS!C3:C11)+COUNTBLANK(PCNS!C13:C19)+COUNTBLANK(KO!C2:C5)+COUNTBLANK(P2R!C2:C61) -> 128 | F39: =$B$7 -> 132
B40: Imprimante ZT | C40: =$B$7-D40-E40 -> 0 | D40: =COUNTIF('Single 1'!D3:D16,"N/A")+COUNTIF('Single 1'!D18:D29,"N/A")+COUNTIF('Single 2'!D3:D16,"N/A")+COUNTIF('Single 2'!D18:D29,"N/A")+COUNTIF(PCNS!D3:D11,"N/A")+COUNTIF(PCNS!D13:D19,"N/A")+COUNTIF(KO!D2:D5,"N/A")+COUNTIF(P2R!D2:D61,"N/A") -> 112 | E40: =COUNTBLANK('Single 1'!D3:D16)+COUNTBLANK('Single 1'!D18:D29)+COUNTBLANK('Single 2'!D3:D16)+COUNTBLANK('Single 2'!D18:D29)+COUNTBLANK(PCNS!D3:D11)+COUNTBLANK(PCNS!D13:D19)+COUNTBLANK(KO!D2:D5)+COUNTBLANK(P2R!D2:D61) -> 20 | F40: =$B$7 -> 132
B42: 6. FOCUS BLOCAGES — À TRAITER EN PRIORITÉ
B43: ="• Câblage à faire ou en cours : "&(E17+D17)&" station(s) sur "&B7 -> • Câblage à faire ou en cours : 11 station(s) sur 132
B44: ="• Secure IT - Câble non conforme : "&D32&" sur "&E32&" saisi(s)" -> • Secure IT - Câble non conforme : 42 sur 52 saisi(s)
B45: ="• Étiquetage non conforme : "&D34&" sur "&E34&" saisi(s)" -> • Étiquetage non conforme : 52 sur 52 saisi(s)
B46: ="• Détail des blocages ponctuels (câbles/pads endommagés, pièces manquantes...) : voir colonne «Commentaire» des onglets process." -> • Détail des blocages ponctuels (câbles/pads endommagés, pièces manquantes...) : voir colonne «Commentaire» des onglets process.
B48: 7. PLANNING & PÉRIMÈTRE PROJET COMPLET
...

Sheet Progression
B2: PROGRESSION DE LA REFONTE — OÙ EN EST CHAQUE PROCESS ?
B3: Statut de câblage (colonne «Câblage fait») par process — Terminé / En cours / À faire, avec volumes.
B5: TABLEAU D'AVANCEMENT PAR PROCESS
B6: Process | C6: Total | D6: Terminé | E6: En cours | F6: À faire | G6: % Terminé
B7: Single 1 | C7: 26 | D7: =COUNTIF('Single 1'!L3:L16,"Fait")+COUNTIF('Single 1'!L18:L29,"Fait") -> 4 | E7: =COUNTIF('Single 1'!L3:L16,"En cours")+COUNTIF('Single 1'!L18:L29,"En cours") -> 1 | F7: =COUNTIF('Single 1'!L3:L16,"A faire")+COUNTIF('Single 1'!L18:L29,"A faire") -> 21 | G7: =D7/C7 -> 0.15384615
B8: Single 2 | C8: 26 | D8: =COUNTIF('Single 2'!L3:L16,"Fait")+COUNTIF('Single 2'!L18:L29,"Fait") -> 6 | E8: =COUNTIF('Single 2'!L3:L16,"En cours")+COUNTIF('Single 2'!L18:L29,"En cours") -> 0 | F8: =COUNTIF('Single 2'!L3:L16,"A faire")+COUNTIF('Single 2'!L18:L29,"A faire") -> 20 | G8: =D8/C8 -> 0.23076923
B9: PCNS 1 | C9: 9 | D9: =COUNTIF(PCNS!L3:L11,"Fait") -> 0 | E9: =COUNTIF(PCNS!L3:L11,"En cours") -> 0 | F9: =COUNTIF(PCNS!L3:L11,"A faire") -> 9 | G9: =D9/C9 -> 0
B10: PCNS 2 | C10: 7 | D10: =COUNTIF(PCNS!L13:L19,"Fait") -> 0 | E10: =COUNTIF(PCNS!L13:L19,"En cours") -> 0 | F10: =COUNTIF(PCNS!L13:L19,"A faire") -> 7 | G10: =D10/C10 -> 0
B11: KO | C11: 4 | D11: =COUNTIF(KO!L2:L5,"Fait") -> 0 | E11: =COUNTIF(KO!L2:L5,"En cours") -> 0 | F11: =COUNTIF(KO!L2:L5,"A faire") -> 4 | G11: =D11/C11 -> 0
B12: P2R | C12: 60 | D12: =COUNTIF(P2R!L2:L61,"Fait") -> 0 | E12: =COUNTIF(P2R!L2:L61,"En cours") -> 0 | F12: =COUNTIF(P2R!L2:L61,"A faire") -> 60 | G12: =D12/C12 -> 0
B13: TOTAL SUIVI | C13: =SUM(C7:C12) -> 132 | D13: =SUM(D7:D12) -> 10 | E13: =SUM(E7:E12) -> 1 | F13: =SUM(F7:F12) -> 121 | G13: =D13/C13 -> 0.075757576
B35: VUE GLOBALE DU PROJET COMPLET (199 STATIONS)
B36: Statut | C36: Stations
B37: Terminé | C37: =D13 -> 10
B38: En cours | C38: =E13 -> 1
B39: À faire (suivi en détail) | C39: =F13 -> 121
B40: Non suivi en détail (autres process) | C40: ='Planning - Calendrier'!B27-C13 -> 67

Sheet Temps
B2: TEMPS — RÉFÉRENCE ET TOTAUX
B4: 1. Temps total restant, par process (colonne «Temps estimé (min)» des onglets process)
B5: Process | C5: Temps estimé restant (min) | D5: Temps estimé restant (h)
B6: Single 1 | C6: =SUM('Single 1'!O3:O16,'Single 1'!O18:O29) -> 3310 | D6: =C6/60 -> 55.166667
B7: Single 2 | C7: =SUM('Single 2'!O3:O16,'Single 2'!O18:O29) -> 3105 | D7: =C7/60 -> 51.75
B8: PCNS 1 | C8: =SUM(PCNS!O3:O11) -> 1350 | D8: =C8/60 -> 22.5
B9: PCNS 2 | C9: =SUM(PCNS!O13:O19) -> 1050 | D9: =C9/60 -> 17.5
B10: KO | C10: =SUM(KO!O2:O5) -> 720 | D10: =C10/60 -> 12
B11: P2R | C11: =SUM(P2R!O2:O61) -> 5400 | D11: =C11/60 -> 90
B12: TOTAL | C12: =SUM(C6:C11) -> 14935 | D12: =C12/60 -> 248.91667
B15: 2. Durées de référence par action (minutes) — méthodologie Pack single, à titre indicatif
B16: Action | C16: Config TC | D16: Remplacement TC | E16: Ajout plaque | F16: Ajout protection câble | G16: Recâblage | H16: Changement position Genovation | I16: Test
B17: Durée (min) | C17: 40 | D17: 10 | E17: 5 | F17: 5 | G17: 120 | H17: 5 | I17: 5

Sheet Single 1
A1: Station | B1: Modèle TC | C1: Imprimante ZD | D1: Imprimante ZT | E1: Genovation déplacé | F1: Scanner remplacé | G1: Système Mask en place | H1: Secure IT - Plaque | I1: Secure IT - Câble | J1: Support 3D pad | K1: Étiquetage | L1: Câblage fait | M1: Autres périphériques | N1: Commentaire | O1: Temps estimé (min)
A2: Stations impaires
A3: wsSingle_01_01 | B3: T655 | D3: N/A | E3: OK | F3: OK | G3: OK | H3: OK | I3: Pas OK | J3: Pas OK | K3: Pas OK | L3: A faire | O3: 130
A4: wsSingle_01_03 | B4: T655 | D4: N/A | E4: OK | F4: OK | G4: OK | H4: OK | I4: Pas OK | J4: Pas OK | K4: Pas OK | L4: En cours | O4: 130
A5: wsSingle_01_05 | B5: T655 | D5: N/A | E5: OK | F5: OK | G5: OK | H5: OK | I5: Pas OK | J5: Pas OK | K5: Pas OK | L5: A faire | O5: 130
A6: wsSingle_01_07 | B6: T655 | D6: N/A | E6: OK | F6: OK | G6: OK | H6: OK | I6: Pas OK | J6: Pas OK | K6: Pas OK | L6: A faire | O6: 130
A7: wsSingle_01_09 | B7: T655 | D7: N/A | E7: OK | F7: OK | G7: OK | H7: OK | I7: Pas OK | J7: Pas OK | K7: Pas OK | L7: A faire | O7: 130
A8: wsSingle_01_11 | B8: T655 | D8: N/A | E8: OK | F8: OK | G8: OK | H8: OK | I8: Pas OK | J8: Pas OK | K8: Pas OK | L8: A faire | O8: 130
A9: wsSingle_01_13 | B9: T655 | D9: N/A | E9: OK | F9: OK | G9: OK | H9: OK | I9: Pas OK | J9: Pas OK | K9: Pas OK | L9: A faire | O9: 130
A10: wsSingle_01_15 | B10: T655 | D10: N/A | E10: OK | F10: OK | G10: OK | H10: OK | I10: Pas OK | J10: Pas OK | K10: Pas OK | L10: A faire | O10: 130
A11: wsSingle_01_17 | B11: T655 | D11: N/A | E11: OK | F11: OK | G11: OK | H11: OK | I11: Pas OK | J11: Pas OK | K11: Pas OK | L11: A faire | O11: 130
A12: wsSingle_01_19 | B12: T655 | D12: N/A | E12: OK | F12: OK | G12: OK | H12: OK | I12: Pas OK | J12: Pas OK | K12: Pas OK | L12: A faire | O12: 130
A13: wsSingle_01_21 | B13: T655 | D13: N/A | E13: OK | F13: OK | G13: OK | H13: OK | I13: Pas OK | J13: Pas OK | K13: Pas OK | L13: A faire | O13: 130
A14: wsSingle_01_23 | B14: T655 | D14: N/A | E14: OK | F14: OK | G14: OK | H14: OK | I14: Pas OK | J14: Pas OK | K14: Pas OK | L14: A faire | O14: 130
A15: wsSingle_01_25 | B15: T655 | D15: N/A | E15: OK | F15: OK | G15: OK | H15: OK | I15: OK | J15: OK | K15: Pas OK | L15: Fait | M15: manque wat-machine | N15: remplacement cable hyperscan | O15: 0
A16: wsSingle_01_27 | B16: T655 | D16: N/A | E16: OK | F16: OK | G16: OK | H16: OK | I16: OK | J16: OK | K16: Pas OK | L16: Fait | N16: reimager le pc manque adm approval + port usb endommage | O16: 0
A17: Stations paires
A18: wsSingle_01_02 | B18: T655 | D18: N/A | E18: OK | F18: OK | G18: OK | H18: OK | I18: Pas OK | J18: Pas OK | K18: Pas OK | L18: A faire | O18: 130
A19: wsSingle_01_04 | B19: T630 | D19: N/A | E19: OK | F19: OK | G19: OK | H19: OK | I19: Pas OK | J19: Pas OK | K19: Pas OK | L19: A faire | O19: 180
A20: wsSingle_01_06 | B20: T630 | D20: N/A | E20: OK | F20: OK | G20: OK | H20: OK | I20: Pas OK | J20: Pas OK | K20: Pas OK | L20: A faire | O20: 180
A21: wsSingle_01_08 | B21: T630 | D21: N/A | E21: OK | F21: OK | G21: OK | H21: OK | I21: Pas OK | J21: Pas OK | K21: Pas OK | L21: A faire | O21: 180
A22: wsSingle_01_10 | B22: T630 | D22: N/A | E22: OK | F22: OK | G22: OK | H22: OK | I22: Pas OK | J22: Pas OK | K22: Pas OK | L22: A faire | M22: manque touche pad numerique | O22: 180
A23: wsSingle_01_12 | B23: T630 | D23: N/A | E23: OK | F23: OK | G23: OK | H23: OK | I23: Pas OK | J23: Pas OK | K23: Pas OK | L23: A faire | O23: 180
A24: wsSingle_01_14 | B24: T630 | D24: N/A | E24: OK | F24: OK | G24: OK | H24: OK | I24: Pas OK | J24: Pas OK | K24: Pas OK | L24: A faire | O24: 180
A25: wsSingle_01_16 | B25: T630 | D25: N/A | E25: OK | F25: OK | G25: OK | H25: OK | I25: Pas OK | J25: Pas OK | K25: Pas OK | L25: A faire | O25: 180
A26: wsSingle_01_18 | B26: T630 | D26: N/A | E26: OK | F26: OK | G26: OK | H26: OK | I26: Pas OK | J26: Pas OK | K26: Pas OK | L26: A faire | O26: 180
A27: wsSingle_01_20 | B27: T630 | D27: N/A | E27: OK | F27: OK | G27: OK | H27: OK | I27: Pas OK | J27: Pas OK | K27: Pas OK | L27: A faire | O27: 180
A28: wsSingle_01_22 | B28: T655 | D28: N/A | E28: OK | F28: OK | G28: OK | H28: OK | I28: OK | J28: OK | K28: Pas OK | L28: Fait | M28: manque touche pad numerique | N28: pad numerique remplacer hub usb changer TC changer | O28: 0
A29: wsSingle_01_24 | B29: T655 | D29: N/A | E29: OK | F29: OK | G29: OK | H29: OK | I29: OK | J29: OK | K29: Pas OK | L29: Fait | M29: RAS | N29: remplacement cable genovation, cable video, ajout d un hib usb et de la protection hyper scan TC changer | O29: 0

Sheet Single 2
A1: Station | B1: Modèle TC | C1: Imprimante ZD | D1: Imprimante ZT | E1: Genovation déplacé | F1: Scanner remplacé | G1: Système Mask en place | H1: Secure IT - Plaque | I1: Secure IT - Câble | J1: Support 3D pad | K1: Étiquetage | L1: Câblage fait | M1: Autres périphériques | N1: Commentaire | O1: Temps estimé (min)
A2: Stations impaires
A3: wsSingle_02_01 | B3: T655 | D3: N/A | E3: OK | F3: OK | G3: OK | H3: OK | I3: OK | J3: OK | K3: Pas OK | L3: Fait | O3: 0
A4: wsSingle_02_03 | B4: T655 | D4: N/A | E4: OK | F4: OK | G4: OK | H4: OK | I4: OK | J4: OK | K4: Pas OK | L4: Fait | N4: cable hyperscan + hub usb remplacer | O4: 0
A5: wsSingle_02_05 | B5: T655 | D5: N/A | E5: OK | F5: OK | G5: OK | H5: OK | I5: OK | J5: OK | K5: Pas OK | L5: Fait | N5: cable hyperscan + hub usb remplacer | O5: 0
A6: wsSingle_02_07 | B6: T655 | D6: N/A | E6: OK | F6: OK | G6: OK | H6: OK | I6: Pas OK | J6: Pas OK | K6: Pas OK | L6: A faire | O6: 130
A7: wsSingle_02_09 | B7: T655 | D7: N/A | E7: OK | F7: OK | G7: OK | H7: OK | I7: Pas OK | J7: Pas OK | K7: Pas OK | L7: A faire | O7: 130
A8: wsSingle_02_11 | B8: T655 | D8: N/A | E8: OK | F8: OK | G8: OK | H8: OK | I8: Pas OK | J8: Pas OK | K8: Pas OK | L8: A faire | O8: 130
A9: wsSingle_02_13 | B9: T655 | D9: N/A | E9: OK | F9: OK | G9: OK | H9: OK | I9: Pas OK | J9: Pas OK | K9: Pas OK | L9: A faire | N9: cable hyperscan abime | O9: 130
A10: wsSingle_02_15 | B10: T655 | D10: N/A | E10: OK | F10: OK | G10: OK | H10: OK | I10: Pas OK | J10: Pas OK | K10: Pas OK | L10: A faire | O10: 130
A11: wsSingle_02_17 | B11: T655 | D11: N/A | E11: OK | F11: OK | G11: OK | H11: OK | I11: Pas OK | J11: Pas OK | K11: Pas OK | L11: A faire | N11: cable hyperscan abime | O11: 130
A12: wsSingle_02_19 | B12: T655 | D12: N/A | E12: OK | F12: OK | G12: OK | H12: OK | I12: Pas OK | J12: Pas OK | K12: Pas OK | L12: A faire | O12: 130
A13: wsSingle_02_21 | B13: T655 | D13: N/A | E13: OK | F13: OK | G13: OK | H13: OK | I13: Pas OK | J13: Pas OK | K13: Pas OK | L13: A faire | O13: 130
A14: wsSingle_02_23 | B14: T655 | D14: N/A | E14: OK | F14: OK | G14: OK | H14: OK | I14: Pas OK | J14: Pas OK | K14: Pas OK | L14: A faire | O14: 130
A15: wsSingle_02_25 | B15: T655 | D15: N/A | E15: OK | F15: OK | G15: OK | H15: OK | I15: OK | J15: OK | K15: Pas OK | L15: Fait | M15: Système de levage | N15: Boutons de réglage de la hauteur de la table d'emballage abîmés | O15: 0
A16: wsSingle_02_27 | B16: T655 | D16: N/A | E16: OK | F16: OK | G16: OK | H16: OK | I16: OK | J16: OK | K16: Pas OK | L16: Fait | N16: remplacement du cable hyperscan | O16: 0
A17: Stations paires
A18: wsSingle_02_02 | B18: T630 | D18: N/A | E18: OK | F18: OK | G18: OK | H18: OK | I18: Pas OK | J18: Pas OK | K18: Pas OK | L18: A faire | O18: 180
A19: wsSingle_02_04 | B19: T655 | D19: N/A | E19: OK | F19: OK | G19: OK | H19: OK | I19: Pas OK | J19: Pas OK | K19: Pas OK | L19: A faire | N19: GOLDEN STATION cable display port en double | O19: 130
A20: wsSingle_02_06 | B20: T630 | D20: N/A | E20: OK | F20: OK | G20: OK | H20: OK | I20: Pas OK | J20: Pas OK | K20: Pas OK | L20: A faire | O20: 180
A21: wsSingle_02_08 | B21: T630 | D21: N/A | E21: OK | F21: OK | G21: OK | H21: OK | I21: Pas OK | J21: Pas OK | K21: Pas OK | L21: A faire | O21: 180
A22: wsSingle_02_10 | B22: T630 | D22: N/A | E22: OK | F22: OK | G22: OK | H22: OK | I22: Pas OK | J22: Pas OK | K22: Pas OK | L22: A faire | O22: 180
A23: wsSingle_02_12 | B23: T630 | D23: N/A | E23: OK | F23: OK | G23: OK | H23: OK | I23: Pas OK | J23: Pas OK | K23: Pas OK | L23: A faire | O23: 180
A24: wsSingle_02_14 | B24: T630 | D24: N/A | E24: OK | F24: OK | G24: OK | H24: OK | I24: Pas OK | J24: Pas OK | K24: Pas OK | L24: A faire | O24: 180
A25: wsSingle_02_16 | B25: T630 | D25: N/A | E25: OK | F25: OK | G25: OK | H25: OK | I25: Pas OK | J25: Pas OK | K25: Pas OK | L25: A faire | O25: 180
A26: wsSingle_02_18 | B26: T630 | D26: N/A | E26: OK | F26: OK | G26: OK | H26: OK | I26: Pas OK | J26: Pas OK | K26: Pas OK | L26: A faire | O26: 180
A27: wsSingle_02_20 | B27: T630 | D27: N/A | E27: OK | F27: OK | G27: OK | H27: OK | I27: Pas OK | J27: Pas OK | K27: Pas OK | L27: A faire | N27: HUB USB remplacer TC remplacer | O27: 180
A28: wsSingle_02_22 | B28: T655 | D28: N/A | E28: OK | F28: OK | G28: OK | H28: OK | I28: Pas OK | J28: Pas OK | K28: Pas OK | L28: A faire | O28: 130
A29: wsSingle_02_24 | B29: T630 | D29: N/A | E29: OK | F29: OK | G29: OK | H29: OK | I29: OK | J29: OK | K29: Pas OK | L29: Fait | N29: Pave numerique remplacer | O29: 55

Sheet PCNS
A1: Station | B1: Modèle TC | C1: Imprimante ZD | D1: Imprimante ZT | E1: Genovation déplacé | F1: Scanner remplacé | G1: Système Mask en place | H1: Secure IT - Plaque | I1: Secure IT - Câble | J1: Support 3D pad | K1: Étiquetage | L1: Câblage fait | M1: Autres périphériques | N1: Commentaire | O1: Temps estimé (min)
A2: PCNS 1 - 9 stations
A3: wsPCNS_1_01 | L3: A faire | O3: 150
A4: wsPCNS_1_02 | L4: A faire | O4: 150
A5: wsPCNS_1_03 | L5: A faire | O5: 150
A6: wsPCNS_1_04 | L6: A faire | O6: 150
A7: wsPCNS_1_05 | L7: A faire | O7: 150
A8: wsPCNS_1_06 | L8: A faire | O8: 150
A9: wsPCNS_1_07 | L9: A faire | O9: 150
A10: wsPCNS_1_08 | L10: A faire | O10: 150
A11: wsPCNS_1_09 | L11: A faire | O11: 150
A12: PCNS 2 - 7 stations
A13: wsPCNS_2_01 | L13: A faire | O13: 150
A14: wsPCNS_2_02 | L14: A faire | O14: 150
A15: wsPCNS_2_03 | L15: A faire | O15: 150
A16: wsPCNS_2_04 | L16: A faire | O16: 150
A17: wsPCNS_2_05 | L17: A faire | O17: 150
A18: wsPCNS_2_06 | L18: A faire | O18: 150
A19: wsPCNS_2_07 | L19: A faire | O19: 150

Sheet KO
A1: Station | B1: Modèle TC | C1: Imprimante ZD | D1: Imprimante ZT | E1: Genovation déplacé | F1: Scanner remplacé | G1: Système Mask en place | H1: Secure IT - Plaque | I1: Secure IT - Câble | J1: Support 3D pad | K1: Étiquetage | L1: Câblage fait | M1: Autres périphériques | N1: Commentaire | O1: Temps estimé (min)
A2: wsKO_01 | C2: N/A | L2: A faire | O2: 180
A3: wsKO_02 | C3: N/A | L3: A faire | O3: 180
A4: wsKO_03 | C4: N/A | L4: A faire | O4: 180
A5: wsKO_04 | C5: N/A | L5: A faire | O5: 180

Sheet P2R
A1: Station | B1: Modèle TC | C1: Imprimante ZD | D1: Imprimante ZT | E1: Genovation déplacé | F1: Scanner remplacé | G1: Système Mask en place | H1: Secure IT - Plaque | I1: Secure IT - Câble | J1: Support 3D pad | K1: Étiquetage | L1: Câblage fait | M1: Autres périphériques | N1: Commentaire | O1: Temps estimé (min)
A2: wsP2R_01 | B2: T655 | D2: N/A | L2: A faire | O2: 90
A3: wsP2R_02 | B3: T655 | D3: N/A | L3: A faire | O3: 90
A4: wsP2R_03 | B4: T655 | D4: N/A | L4: A faire | O4: 90
A5: wsP2R_04 | B5: T655 | D5: N/A | L5: A faire | O5: 90
A6: wsP2R_05 | B6: T655 | D6: N/A | L6: A faire | O6: 90
A7: wsP2R_06 | B7: T655 | D7: N/A | L7: A faire | O7: 90
A8: wsP2R_07 | B8: T655 | D8: N/A | L8: A faire | O8: 90
A9: wsP2R_08 | B9: T655 | D9: N/A | L9: A faire | O9: 90
A10: wsP2R_09 | B10: T655 | D10: N/A | L10: A faire | O10: 90
A11: wsP2R_10 | B11: T655 | D11: N/A | L11: A faire | O11: 90
A12: wsP2R_11 | B12: T655 | D12: N/A | L12: A faire | O12: 90
A13: wsP2R_12 | B13: T655 | D13: N/A | L13: A faire | O13: 90
... A61: wsP2R_60 | B61: T655 | D61: N/A | L61: A faire | O61: 90
